<?xml version="1.0"?>
<!-- created with Phobos 1.0.1 "Capricious Choutengan" -->
  <robot name="bittle">

    <link name="base-frame-link">
      <inertial>
        <origin xyz="0 0 0" rpy="0 0 0"/>
        <mass value="0.108"/>
        <inertia ixx="0.01562" ixy="0" ixz="-2e-05" iyy="0.00613" iyz="0" izz="0.02107"/>
      </inertial>
      <visual name="base_frame">
        <origin xyz="0 0 0" rpy="0 0 0"/>
        <geometry>
          <box size="0.98 1.29 00.28"/>
        </geometry>
      </visual>
      <collision name="base_frame_c">
        <origin xyz="0 0 0" rpy="0 0 0"/>
        <geometry>
          <box size="0.98 1.29 00.28"/>
        </geometry>
      </collision>
    </link>

    <link name="left-front-shoulder-link">
      <inertial>
        <origin xyz="0 -0.24575 0.0777" rpy="0 0 0"/>
        <mass value="0.006"/>
        <inertia ixx="0.00044" ixy="0" ixz="0" iyy="2e-05" iyz="0" izz="0.00044"/>
      </inertial>
      <visual name="left_front_shoulder">
        <origin xyz="0 -0.24575 0.0777" rpy="-1.5708 1.5708 0"/>
        <geometry>
          <box size="0.13 0.15 0.62"/>
        </geometry>
      </visual>
      <collision name="left_front_shoulder_c">
        <origin xyz="0 -0.24575 0.0777" rpy="-1.5708 1.5708 0"/>
        <geometry>
          <box size="0.13 0.15 0.62"/>
        </geometry>
      </collision>
    </link>
	
	 <link name="left-front-knee-link">
      <inertial>
        <origin xyz="0.09497 0.23488 -0.1382" rpy="0 0 0"/>
        <mass value="0.017"/>
        <inertia ixx="6e-05" ixy="-2e-05" ixz="0" iyy="0.00065" iyz="-6e-05" izz="0.00063"/>
      </inertial>
      <visual name="left_front_knee">
        <origin xyz="0.09497 0.23488 -0.1382" rpy="-1.5708 1.5708 0"/>
        <geometry>
          <capsule radius="0.0845" length="0.634"/>
        </geometry>
      </visual>
      <collision name="left_front_knee_c">
        <origin xyz="0.09497 0.23488 -0.1382" rpy="-1.5708 1.5708 0"/>
        <geometry>
          <capsule radius="0.0845" length="0.634"/>
        </geometry>
      </collision>
    </link>
	
    <link name="right-back-knee-link">
      <inertial>
        <origin xyz="0.08426 -0.23488 -0.1382" rpy="0 0 0"/>
        <mass value="0.017"/>
        <inertia ixx="6e-05" ixy="-1e-05" ixz="0" iyy="0.00065" iyz="-3e-05" izz="0.00064"/>
      </inertial>
      <visual name="right_back_knee">
        <origin xyz="0.08426 -0.23488 -0.1382" rpy="-1.5708 -1.5708 0"/>
        <geometry>
          <capsule radius="0.0845" length="0.465"/>
        </geometry>
      </visual>
      <collision name="right_back_knee_c">
        <origin xyz="0.08426 -0.23488 -0.1382" rpy="-1.5708 -1.5708 0"/>
        <geometry>
          <capsule radius="0.0845" length="0.465"/>
        </geometry>
      </collision>
    </link>

    <link name="right-back-shoulder-link">
      <inertial>
        <origin xyz="0 0.24575 0.0777" rpy="0 0 0"/>
        <mass value="0.006"/>
        <inertia ixx="0.00044" ixy="0" ixz="0" iyy="2e-05" iyz="0" izz="0.00044"/>
      </inertial>
      <visual name="right_back_shoulder">
        <origin xyz="0 0.24575 0.0777" rpy="1.5708 -1.5708 0"/>
        <geometry>
          <box size="0.13 0.15 0.62"/>
        </geometry>
      </visual>
      <collision name="right_back_shoulder_c">
        <origin xyz="0 0.24575 0.0777" rpy="1.5708 -1.5708 0"/>
        <geometry>
          <box size="0.13 0.15 0.62"/>
        </geometry>
      </collision>
    </link>

    <link name="right-front-shoulder-link">
      <inertial>
        <origin xyz="0 0.24575 0.0777" rpy="0 0 0"/>
        <mass value="0.006"/>
        <inertia ixx="0.00044" ixy="0" ixz="0" iyy="2e-05" iyz="0" izz="0.00044"/>
      </inertial>
      <visual name="right_front_shoulder">
        <origin xyz="0 0.24575 0.0777" rpy="1.5708 -1.5708 0"/>
        <geometry>
          <box size="0.13 0.15 0.62"/>
        </geometry>
      </visual>
      <collision name="right_front_shoulder_c">
        <origin xyz="0 0.24575 0.0777" rpy="1.5708 -1.5708 0"/>
        <geometry>
          <box size="0.13 0.15 0.62"/>
        </geometry>
      </collision>
    </link>
	
    <link name="right-front-knee-link">
      <inertial>
        <origin xyz="0.09497 -0.23488 -0.1382" rpy="0 0 0"/>
        <mass value="0.017"/>
        <inertia ixx="6e-05" ixy="-1e-05" ixz="0" iyy="0.00065" iyz="-3e-05" izz="0.00064"/>
      </inertial>
      <visual name="right_front_knee">
        <origin xyz="0.09497 -0.23488 -0.1382" rpy="-1.5708 -1.5708 0"/>
        <geometry>
          <capsule radius="0.0845" length="0.465"/>
        </geometry>
      </visual>
      <collision name="right_front_knee_c">
        <origin xyz="0.09497 -0.23488 -0.1382" rpy="-1.5708 -1.5708 0"/>
        <geometry>
          <capsule radius="0.0845" length="0.465"/>
        </geometry>
      </collision>
    </link>
	
    <joint name="left-front-shoulder-joint" type="revolute">
      <origin xyz="-0.44596 0.52264 -0.02102" rpy="1.5708 0 -1.5708"/>
      <parent link="base-frame-link"/>
      <child link="left-front-shoulder-link"/>
      <axis xyz="0 0 1.0"/>
      <limit lower="-1.5708" upper="1.22173" effort="1.0" velocity="1.5708"/>
    </joint>

    <joint name="left-front-knee-joint" type="revolute">
      <origin xyz="0.13 0.465 0.0777" rpy="0 0 0"/>
      <parent link="left-front-shoulder-link"/>
      <child link="left-front-knee-link"/>
      <axis xyz="0 0 1.0"/>
      <limit lower="-1.22173" upper="1.48353" effort="1.0" velocity="1.5708"/>
    </joint>

    <joint name="right-back-knee-joint" type="revolute">
      <origin xyz="0.13 0.465 0.0777" rpy="0 0 3.14159"/>
      <parent link="right-back-shoulder-link"/>
      <child link="right-back-knee-link"/>
      <axis xyz="0 0 1.0"/>
      <limit lower="-1.22173" upper="1.48353" effort="1.0" velocity="1.5708"/>
    </joint>

    <joint name="right-back-shoulder-joint" type="revolute">
      <origin xyz="0.45149 -0.51923 -0.02102" rpy="-1.5708 0 -1.5708"/>
      <parent link="base-frame-link"/>
      <child link="right-back-shoulder-link"/>
      <axis xyz="0 0 1.0"/>
      <limit lower="-1.5708" upper="1.22173" effort="1.0" velocity="1.5708"/>
    </joint>

    <joint name="right-front-knee-joint" type="revolute">
      <origin xyz="0.13 0.465 0.0777" rpy="0 0 3.14159"/>
      <parent link="right-front-shoulder-link"/>
      <child link="right-front-knee-link"/>
      <axis xyz="0 0 1.0"/>
      <limit lower="-1.22173" upper="1.48353" effort="1.0" velocity="1.5708"/>
    </joint>

    <joint name="right-front-shoulder-joint" type="revolute">
      <origin xyz="0.45149 0.52264 -0.02102" rpy="-1.5708 0 -1.5708"/>
      <parent link="base-frame-link"/>
      <child link="right-front-shoulder-link"/>
      <axis xyz="0 0 1.0"/>
      <limit lower="-1.5708" upper="1.22173" effort="1.0" velocity="1.5708"/>
    </joint>

  </robot>
